Workbook

Sheet Read me
A1: Body assessment workbook (men and women)
A2: What to edit
A3: Yellow cells with blue text are inputs. Everything else is a formula.
A4: Measurements: one column per date (date in row 1). Enter sex (male or female) in each column: it selects the body-fat, strength, fitness, size and proportion models. The example column is a typical recreational woman; overwrite or delete it. Leave unmeasured cells blank.
A5: Report!B2: analysis date. It defaults to the latest date; type a date to analyse an earlier column.
A6: Parameters: shared constants, a sex-specific table (male / female / in use), ideal ratios (each tagged male or female), lift factors for each sex, and model sources.
A7: Required inputs
A8: Everyone: height, weight, age, sex, neck and waist; wrist and ankle (men's size ceiling). Women also need hips (body fat and proportion). Missing girths blank out their own rows only.
A9: Sheets
A10: Summary: five attributes on 0-1 scales (leanness, fitness, strength, size, proportion), each measured once, combined by a weighted geometric mean.
A11: Weights: Purposes sheet (rank health, looks and performance; simplest) or Attributes sheet (rank the five attributes directly; full control; 0 points leaves one out). Summary!B3 chooses which one drives the composite. Both default to equal ranks.
A12: Report: body composition, fitness, proportion, left/right symmetry, size ceilings. Strength: Symmetric Strength method (1RMs, rep maxes, scores, tiers, symmetry, Wilks, muscle groups). Plan: waist milestones, cardio targets, strength and size priorities, tiers per muscle group, exercises ranked.
... A28: Default rankings are neutral. Nothing in the workbook assumes what a woman (or a man) should value; set your own weights.

Sheet Measurements
A1: key | B1: Measurement | C1: Unit | D1: Protocol | E1: 46266
A2: height | B2: Height | C2: cm | D2: Barefoot, standing tall | E2: 164
A3: weight | B3: Body weight | C3: kg | D3: Morning, after toilet, before food | E3: 66
A4: age | B4: Age | C4: years | D4: Age in whole years on this date | E4: 38
A5: sex | B5: Sex | C5: male/female | D5: male or female: selects the body-fat, strength, fitness, size and proportion models (see Read me for the female limitations) | E5: female
A6: neck | B6: Neck | C6: cm | D6: Below the Adam's apple, smallest point | E6: 32
A7: shoulders | B7: Shoulders | C7: cm | D7: Around both deltoids at widest point, arms at sides | E7: 102
A8: chest | B8: Chest (for proportions) | C8: cm | D8: Largest girth under the armpits, chest held as you normally stand; for the classical ratios | E8: 92
A9: chest_relaxed | B9: Chest, relaxed (for Butt) | C9: cm | D9: Nipple level, arms at sides, normal breathing; not expanded, lats not flared (Casey Butt) | E9: 90
A10: waist | B10: Waist | C10: cm | D10: Men: horizontal at the navel. Women: at the narrowest point (natural waist). Standing, end of a normal exhalation, belly neither pulled in nor pushed out (US Navy) | E10: 76
A11: hips | B11: Hips | C11: cm | D11: Widest point of the buttocks, feet together. Required for women (body fat and proportion) | E11: 100
A12: wrist_l | B12: Wrist (left) | C12: cm | D12: Hand side of the styloid process (bony lump) | E12: 15
A13: wrist_r | B13: Wrist (right) | C13: cm | D13: Hand side of the styloid process (bony lump) | E13: 15
A14: forearm_l | B14: Forearm (left) | C14: cm | D14: Fist clenched, arm straight, largest point | E14: 23.5
A15: forearm_r | B15: Forearm (right) | C15: cm | D15: Fist clenched, arm straight, largest point | E15: 24
A16: arm_l | B16: Upper arm (left) | C16: cm | D16: Flexed, largest point | E16: 28
A17: arm_r | B17: Upper arm (right) | C17: cm | D17: Flexed, largest point | E17: 28.5
... A31: squat_reps | B31: Back squat: reps | C31: reps | D31: Reps to failure, whole number 1-10 (decimals are rounded down) | E31: 5
A32: front_squat_load | B32: Front squat: load | C32: kg | D32: Below parallel, no knee wraps. Total weight: bar + plates + collars
A33: front_squat_reps | B33: Front squat: reps | C33: reps | D33: Reps to failure, whole number 1-10 (decimals are rounded down)
A34: leg_press_load | B34: 45-degree leg press: load | C34: kg | D34: 45-degree sled; load = sled + plates; hips stay on the pad | E34: 120
A35: leg_press_reps | B35: 45-degree leg press: reps | C35: reps | D35: Reps to failure, whole number 1-10 (decimals are rounded down) | E35: 10
A36: deadlift_load | B36: Deadlift: load | C36: kg | D36: Conventional, no straps. Total weight: bar + plates + collars | E36: 70
A37: deadlift_reps | B37: Deadlift: reps | C37: reps | D37: Reps to failure, whole number 1-10 (decimals are rounded down) | E37: 5
A38: sumo_deadlift_load | B38: Sumo deadlift: load | C38: kg | D38: Sumo stance, no straps. Total weight: bar + plates + collars
A39: sumo_deadlift_reps | B39: Sumo deadlift: reps | C39: reps | D39: Reps to failure, whole number 1-10 (decimals are rounded down)
A40: power_clean_load | B40: Power clean: load | C40: kg | D40: From the floor, racked on the shoulders. Total weight: bar + plates + collars
A41: power_clean_reps | B41: Power clean: reps | C41: reps | D41: Reps to failure, whole number 1-10 (decimals are rounded down)
A42: bench_load | B42: Bench press: load | C42: kg | D42: One-second pause on the chest. Total weight: bar + plates + collars | E42: 32.5
A43: bench_reps | B43: Bench press: reps | C43: reps | D43: Reps to failure, whole number 1-10 (decimals are rounded down) | E43: 5
A44: incline_bench_load | B44: Incline bench press: load | C44: kg | D44: 30-45 degree bench, pause on the chest. Total weight: bar + plates + collars
A45: incline_bench_reps | B45: Incline bench press: reps | C45: reps | D45: Reps to failure, whole number 1-10 (decimals are rounded down)
A46: dip_load | B46: Dip: load | C46: kg added | D46: Upper arms below parallel. Load = added weight (negative if assisted)
A47: dip_reps | B47: Dip: reps | C47: reps | D47: Reps to failure, whole number 1-10 (decimals are rounded down)
A48: ohp_load | B48: Overhead press: load | C48: kg | D48: Standing, strict. Total weight: bar + plates + collars | E48: 25
A49: ohp_reps | B49: Overhead press: reps | C49: reps | D49: Reps to failure, whole number 1-10 (decimals are rounded down) | E49: 5
A50: push_press_load | B50: Push press: load | C50: kg | D50: Dip and drive. Total weight: bar + plates + collars
A51: push_press_reps | B51: Push press: reps | C51: reps | D51: Reps to failure, whole number 1-10 (decimals are rounded down)
A52: snatch_press_load | B52: Snatch press: load | C52: kg | D52: Snatch grip, bar from behind the neck. Total weight: bar + plates + collars
A53: snatch_press_reps | B53: Snatch press: reps | C53: reps | D53: Reps to failure, whole number 1-10 (decimals are rounded down)
...

Sheet Summary
A1: Summary: five attributes, each measured once
A2: Analysis date | B2: =r_date -> 46266
A3: Weights from | B3: purposes | C3: purposes = rank health, looks and performance (Purposes sheet); attributes = rank the five attributes directly (Attributes sheet)
A4: attribute | B4: score (0-1) | C4: share in use | D4: ln(score) | E4: definition
A5: Leanness | B5: =MAX(0,MIN(1,(p_whtr_zero-m_waist/m_height)/(p_whtr_zero-p_whtr_best))) -> 0.91056911 | C5: =IF(c_mode="purposes",Purposes!$B$12,Attributes!$E$4) -> 0.22222222 | D5: =IF(OR(B5="",B5<=0),"",LN(B5)) -> -0.093685484 | E5: Waist-to-height: 1 at or below 0.45, 0 at or above 0.6, linear between. The only attribute that uses the waist | J5: =IF(D5="",0,D5) -> -0.093685484 | L5: =IF(B5="",0,1) -> 1
A6: Fitness | B6: =IF(r_fit_pct="","",r_fit_pct/100) -> 0.60577724 | C6: =IF(c_mode="purposes",Purposes!$B$13,Attributes!$E$5) -> 0.27777778 | D6: =IF(OR(B6="",B6<=0),"",LN(B6)) -> -0.50124294 | E6: Estimated VO2max as a percentile of people of your sex and age (FRIEND) / 100. Blank until a test is entered | J6: =IF(D6="",0,D6) -> -0.50124294 | L6: =IF(B6="",0,1) -> 1
A7: Strength | B7: =s_gm/p_strength_ref -> 0.48386556 | C7: =IF(c_mode="purposes",Purposes!$B$14,Attributes!$E$6) -> 0.27777778 | D7: =IF(OR(B7="",B7<=0),"",LN(B7)) -> -0.72594818 | E7: Relative strength: geometric mean of category scores / 100 (100 = age-adjusted Wilks 400, balanced) | J7: =IF(D7="",0,D7) -> -0.72594818 | L7: =IF(B7="",0,1) -> 1
A8: Size | B8: =r_lbm/r_size_ceiling -> 0.71157044 | C8: =IF(c_mode="purposes",Purposes!$B$15,Attributes!$E$7) -> 0.11111111 | D8: =IF(OR(B8="",B8<=0),"",LN(B8)) -> -0.34028086 | E8: Lean mass / natural ceiling (men: Casey Butt, frame-based; women: FFMI 23.9 x height^2, Harty 2019) | J8: =IF(D8="",0,D8) -> -0.34028086 | L8: =IF(B8="",0,1) -> 1
A9: Proportion | B9: =IF(r_aes_dist="","",1/(1+r_aes_dist)) -> 0.96086944 | C9: =IF(c_mode="purposes",Purposes!$B$16,Attributes!$E$8) -> 0.11111111 | D9: =IF(OR(B9="",B9<=0),"",LN(B9)) -> -0.039916742 | E9: Shape: exp(-RMS log deviation from the ideal ratios for your sex. Excludes the waist. Women: only two ratios (hips, shoulders/hips) | J9: =IF(D9="",0,D9) -> -0.039916742 | L9: =IF(B9="",0,1) -> 1
A11: Composite (attribute ranking) | B11: =c_attr -> 0.71161742
A12: Composite (purpose ranking) | B12: =c_purp -> 0.66767777
A13: Composite in use | B13: =IF(c_mode="purposes",c_purp,c_attr) -> 0.66767777 | E13: Weighted geometric mean over the attributes that have data: a weak attribute cannot be bought back by a strong one
A14: Weakest attribute | B14: =INDEX($A$5:$A$9,MATCH(MIN($B$5:$B$9),$B$5:$B$9,0)) -> Strength
A16: Couplings: a smaller waist also raises relative strength (Wilks rewards lower bodyweight) and fitness (VO2max is per kg), so these attributes are less independent than their weights suggest.

Sheet Attributes
A1: Rank the five attributes directly (for users who want full control)
A2: Used when Summary!B3 = attributes. Rank 1 = most important, ties allowed; each weight is 1/rank. Or type points (any scale), which override the ranks; 0 points leaves an attribute out, e.g. size for someone not interested in it. Each measurement counts once: proportion excludes the waist, which is scored only under leanness.
A3: attribute | B3: rank | C3: points | D3: weight used | E3: share | F3: score | G3: what it measures
A4: Leanness | B4: 1 | D4: =IF(Summary!$B$5="",0,IF(SUM($C$4:$C$8)>0,N(C4),IF(B4="",0,1/B4))) -> 1 | E4: =D4/SUM($D$4:$D$8) -> 0.2 | F4: =Summary!$B$5 -> 0.91056911 | G4: Waist-to-height: 1 at or below 0.45, 0 at or above 0.6, linear between. The only attribute that uses the waist
A5: Fitness | B5: 1 | D5: =IF(Summary!$B$6="",0,IF(SUM($C$4:$C$8)>0,N(C5),IF(B5="",0,1/B5))) -> 1 | E5: =D5/SUM($D$4:$D$8) -> 0.2 | F5: =Summary!$B$6 -> 0.60577724 | G5: Estimated VO2max as a percentile of people of your sex and age (FRIEND) / 100. Blank until a test is entered
A6: Strength | B6: 1 | D6: =IF(Summary!$B$7="",0,IF(SUM($C$4:$C$8)>0,N(C6),IF(B6="",0,1/B6))) -> 1 | E6: =D6/SUM($D$4:$D$8) -> 0.2 | F6: =Summary!$B$7 -> 0.48386556 | G6: Relative strength: geometric mean of category scores / 100 (100 = age-adjusted Wilks 400, balanced)
A7: Size | B7: 1 | D7: =IF(Summary!$B$8="",0,IF(SUM($C$4:$C$8)>0,N(C7),IF(B7="",0,1/B7))) -> 1 | E7: =D7/SUM($D$4:$D$8) -> 0.2 | F7: =Summary!$B$8 -> 0.71157044 | G7: Lean mass / natural ceiling (men: Casey Butt, frame-based; women: FFMI 23.9 x height^2, Harty 2019)
A8: Proportion | B8: 1 | D8: =IF(Summary!$B$9="",0,IF(SUM($C$4:$C$8)>0,N(C8),IF(B8="",0,1/B8))) -> 1 | E8: =D8/SUM($D$4:$D$8) -> 0.2 | F8: =Summary!$B$9 -> 0.96086944 | G8: Shape: exp(-RMS log deviation from the ideal ratios for your sex. Excludes the waist. Women: only two ratios (hips, shoulders/hips)
A10: Composite (attribute ranking) | B10: =IF(MIN(Summary!$B$5:$B$9)<=0,0,EXP(SUMPRODUCT($D$4:$D$8,Summary!$J$5:$J$9)/SUM($D$4:$D$8))) -> 0.71161742
A13: Purposes view of this ranking (read-only)
A14: Each attribute's share is split equally among the purposes it serves; the purpose score is the geometric mean of its attributes weighted by your attribute ranks. This reads the attribute ranking in purpose terms; it is not the inverse of the Purposes sheet.
A15: purpose | B15: share of your weight | C15: score | D15: attributes
A16: Health | B16: =SUMPRODUCT($E$4:$E$8,Parameters!$B$251:$B$255/Parameters!$E$251:$E$255) -> 0.3 | C16: =IF(SUMPRODUCT($D$4:$D$8,Parameters!$B$251:$B$255)=0,"",EXP(SUMPRODUCT($D$4:$D$8,Parameters!$B$251:$B$255,Summary!$J$5:$J$9)/SUMPRODUCT($D$4:$D$8,Parameters!$B$251:$B$255))) -> 0.64384826 | D16: Leanness, fitness, strength
A17: Looks | B17: =SUMPRODUCT($E$4:$E$8,Parameters!$C$251:$C$255/Parameters!$E$251:$E$255) -> 0.5 | C17: =IF(SUMPRODUCT($D$4:$D$8,Parameters!$C$251:$C$255)=0,"",EXP(SUMPRODUCT($D$4:$D$8,Parameters!$C$251:$C$255,Summary!$J$5:$J$9)/SUMPRODUCT($D$4:$D$8,Parameters!$C$251:$C$255))) -> 0.85388306 | D17: Leanness, size, proportion
A18: Performance | B18: =SUMPRODUCT($E$4:$E$8,Parameters!$D$251:$D$255/Parameters!$E$251:$E$255) -> 0.2 | C18: =IF(SUMPRODUCT($D$4:$D$8,Parameters!$D$251:$D$255)=0,"",EXP(SUMPRODUCT($D$4:$D$8,Parameters!$D$251:$D$255,Summary!$J$5:$J$9)/SUMPRODUCT($D$4:$D$8,Parameters!$D$251:$D$255))) -> 0.54140073 | D18: Strength, fitness

Sheet Purposes
A1: Rank purposes instead of attributes
A2: Each purpose score is the equal-weight geometric mean of the attributes that serve it (Parameters table); the composite is the weighted geometric mean of the purpose scores. Used when Summary!B3 = purposes.
A3: purpose | B3: rank | C3: points | D3: weight used | E3: share | F3: score | G3: attributes
A4: Health | B4: 1 | D4: =IF(F4="",0,IF(SUM($C$4:$C$6)>0,N(C4),IF(B4="",0,1/B4))) -> 1 | E4: =D4/SUM($D$4:$D$6) -> 0.33333333 | F4: =IF(I4=0,"",EXP(SUMPRODUCT(Parameters!$B$251:$B$255,Summary!$L$5:$L$9,Summary!$J$5:$J$9)/I4)) -> 0.64384826 | G4: Leanness, fitness, strength | H4: =IF(F4="",0,IF(F4<=0,-1000,LN(F4))) -> -0.4402922 | I4: =SUMPRODUCT(Parameters!$B$251:$B$255,Summary!$L$5:$L$9) -> 3
A5: Looks | B5: 1 | D5: =IF(F5="",0,IF(SUM($C$4:$C$6)>0,N(C5),IF(B5="",0,1/B5))) -> 1 | E5: =D5/SUM($D$4:$D$6) -> 0.33333333 | F5: =IF(I5=0,"",EXP(SUMPRODUCT(Parameters!$C$251:$C$255,Summary!$L$5:$L$9,Summary!$J$5:$J$9)/I5)) -> 0.85388306 | G5: Leanness, size, proportion | H5: =IF(F5="",0,IF(F5<=0,-1000,LN(F5))) -> -0.15796103 | I5: =SUMPRODUCT(Parameters!$C$251:$C$255,Summary!$L$5:$L$9) -> 3
A6: Performance | B6: 1 | D6: =IF(F6="",0,IF(SUM($C$4:$C$6)>0,N(C6),IF(B6="",0,1/B6))) -> 1 | E6: =D6/SUM($D$4:$D$6) -> 0.33333333 | F6: =IF(I6=0,"",EXP(SUMPRODUCT(Parameters!$D$251:$D$255,Summary!$L$5:$L$9,Summary!$J$5:$J$9)/I6)) -> 0.54140073 | G6: Strength, fitness | H6: =IF(F6="",0,IF(F6<=0,-1000,LN(F6))) -> -0.61359556 | I6: =SUMPRODUCT(Parameters!$D$251:$D$255,Summary!$L$5:$L$9) -> 2
A8: Composite (purpose ranking) | B8: =IF(MIN($F$4:$F$6)<=0,0,EXP(SUMPRODUCT($D$4:$D$6,$H$4:$H$6)/SUM($D$4:$D$6))) -> 0.66767777
A10: What this ranking means per attribute
A11: attribute | B11: effective share
A12: Leanness | B12: =Summary!$L$5*(IF($I$4=0,0,$E$4*Parameters!$B$251/$I$4)+IF($I$5=0,0,$E$5*Parameters!$C$251/$I$5)+IF($I$6=0,0,$E$6*Parameters!$D$251/$I$6)) -> 0.22222222
A13: Fitness | B13: =Summary!$L$6*(IF($I$4=0,0,$E$4*Parameters!$B$252/$I$4)+IF($I$5=0,0,$E$5*Parameters!$C$252/$I$5)+IF($I$6=0,0,$E$6*Parameters!$D$252/$I$6)) -> 0.27777778
A14: Strength | B14: =Summary!$L$7*(IF($I$4=0,0,$E$4*Parameters!$B$253/$I$4)+IF($I$5=0,0,$E$5*Parameters!$C$253/$I$5)+IF($I$6=0,0,$E$6*Parameters!$D$253/$I$6)) -> 0.27777778
A15: Size | B15: =Summary!$L$8*(IF($I$4=0,0,$E$4*Parameters!$B$254/$I$4)+IF($I$5=0,0,$E$5*Parameters!$C$254/$I$5)+IF($I$6=0,0,$E$6*Parameters!$D$254/$I$6)) -> 0.11111111
A16: Proportion | B16: =Summary!$L$9*(IF($I$4=0,0,$E$4*Parameters!$B$255/$I$4)+IF($I$5=0,0,$E$5*Parameters!$C$255/$I$5)+IF($I$6=0,0,$E$6*Parameters!$D$255/$I$6)) -> 0.11111111
A17: Check: composite from these effective shares | B17: =IF(MIN(Summary!$B$5:$B$9)<=0,0,EXP(SUMPRODUCT($B$12:$B$16,Summary!$J$5:$J$9))) -> 0.66767777
A19: Each purpose's share is split equally among its attributes that have data, so an attribute serving two purposes collects from both. Ranking purposes fixes the attribute weights; ranking attributes does not fix a unique purpose split, which is why the two directions do not round-trip.

Sheet Plan
A1: Plan: where effort pays
A2: Analysis date | B2: =r_date -> 46266
A3: For the size of each lever's effect on the composite, see the notebook's lever ranking. Tiers below are rule-based and editable on Parameters.
A5: 1. Leanness: waist, mostly through diet
A6: milestone | B6: waist (cm) | C6: waist/height | D6: body fat (Navy) | E6: weight at current lean mass (kg) | F6: fat to lose (kg) | G6: weeks at brisk pace | H6: weeks at gentle pace
A7: Now | B7: =m_waist -> 76 | C7: =B7/m_height -> 0.46341463 | D7: =(p_navy_k1/(p_navy_a-p_navy_b*LOG10(B7+p_navy_hip*N(m_hips)-m_neck)+p_navy_c*LOG10(m_height))-p_navy_k2)/100 -> 0.30695799 | E7: =r_lbm/(1-D7) -> 66 | F7: =MAX(0,m_weight-E7) -> 0 | G7: =F7/(p_loss_rate_hi*m_weight) -> 0 | H7: =F7/(p_loss_rate_lo*m_weight) -> 0
A8: Waist-to-height 0.5 boundary | B8: =p_whtr_limit*m_height -> 82 | C8: =B8/m_height -> 0.5 | D8: =(p_navy_k1/(p_navy_a-p_navy_b*LOG10(B8+p_navy_hip*N(m_hips)-m_neck)+p_navy_c*LOG10(m_height))-p_navy_k2)/100 -> 0.3361025 | E8: =r_lbm/(1-D8) -> 68.897342 | F8: =MAX(0,m_weight-E8) -> 0 | G8: =F8/(p_loss_rate_hi*m_weight) -> 0 | H8: =F8/(p_loss_rate_lo*m_weight) -> 0
A9: Full leanness score (whtr_best) | B9: =p_whtr_best*m_height -> 73.8 | C9: =B9/m_height -> 0.45 | D9: =(p_navy_k1/(p_navy_a-p_navy_b*LOG10(B9+p_navy_hip*N(m_hips)-m_neck)+p_navy_c*LOG10(m_height))-p_navy_k2)/100 -> 0.29605738 | E9: =r_lbm/(1-D9) -> 64.977985 | F9: =MAX(0,m_weight-E9) -> 1.0220148 | G9: =F9/(p_loss_rate_hi*m_weight) -> 1.5485073 | H9: =F9/(p_loss_rate_lo*m_weight) -> 3.0970146
A10: Weights assume lean mass is kept.
A11: Calorie deficit | B11: ="Aim to lose "&TEXT(p_loss_rate_lo*m_weight,"0.0")&"-"&TEXT(p_loss_rate_hi*m_weight,"0.0")&" kg a week; diet does most of the work." -> Aim to lose 0.3-0.7 kg a week; diet does most of the work.
A12: Protein | B12: ="About "&TEXT(p_protein_lo*m_weight,"0")&"-"&TEXT(p_protein_hi*m_weight,"0")&" g a day ("&p_protein_lo&"-"&p_protein_hi&" g/kg), to keep muscle while losing fat." -> About 106-145 g a day (1.6-2.2 g/kg), to keep muscle while losing fat.
A13: Lifting | B13: ="Keep lifting hard while losing fat: it is what preserves lean mass. Novice strength still rises in a modest deficit." -> Keep lifting hard while losing fat: it is what preserves lean mass. Novice strength still rises in a modest deficit.
A15: 2. Fitness: cardio
B16: VO2max (ml/kg/min) | C16: percentile
A17: Now (mean of tests entered) | B17: =Report!$B$63 -> 31.150208 | C17: =r_fit_pct -> 60.577724
A18: Needed for the 50th percentile (treadmill norms, your age) | B18: =INDEX(t_friend_vals,MATCH(m_sex&"|treadmill|"&MIN(80,MAX(20,INT(m_age/10)*10)),t_friend_keys,0),5) -> 28.3 | C18: 50
A19: Needed for the 70th percentile (treadmill norms, your age) | B19: =INDEX(t_friend_vals,MATCH(m_sex&"|treadmill|"&MIN(80,MAX(20,INT(m_age/10)*10)),t_friend_keys,0),7) -> 33.6 | C19: 70
A20: Needed for the 90th percentile (treadmill norms, your age) | B20: =INDEX(t_friend_vals,MATCH(m_sex&"|treadmill|"&MIN(80,MAX(20,INT(m_age/10)*10)),t_friend_keys,0),9) -> 42.1 | C20: 90
A21: Test | B21: ="No test yet? The Rockport 1-mile walk is the safest start; a timed 5 km or a Cooper 12-minute run once running is comfortable." -> No test yet? The Rockport 1-mile walk is the safest start; a timed 5 km or a Cooper 12-minute run once running is comfortable.
A22: Volume | B22: ="150-300 min a week moderate, or 75-150 vigorous (WHO 2020). Also adds to the calorie deficit." -> 150-300 min a week moderate, or 75-150 vigorous (WHO 2020). Also adds to the calorie deficit.
A23: Intensity | B23: ="Once a base is built, one or two interval sessions a week (e.g. 4 x 4 min hard, 3 min easy) raise VO2max faster than steady work alone (Helgerud et al. 2007)." -> Once a base is built, one or two interval sessions a week (e.g. 4 x 4 min hard, 3 min easy) raise VO2max faster than steady work alone (Helgerud et al. 2007).
A24: Modes | B24: ="Anything counts for training, including the elliptical; only the test needs a standard mode." -> Anything counts for training, including the elliptical; only the test needs a standard mode.
A26: 3. Scored lifts: where strength gains pay most
A27: In the geometric mean every category is worth the same per percent of improvement; the weakest lift is usually the cheapest to raise by a given percent (technique, untapped headroom), so it gets the most work.
A28: category | B28: best lift | C28: vs overall | D28: class | E28: tier
A29: squat | B29: =INDEX(Strength!$D$33:$D$37,MATCH(A29,s_cat_names,0)) -> Back squat | C29: =INDEX(Strength!$E$33:$E$37,MATCH(A29,s_cat_names,0)) -> -0.10895235 | D29: =INDEX(s_cat_class,MATCH(A29,s_cat_names,0)) -> weak | E29: =IF(D29="weak","hard",IF(D29="strong","maintenance",IF(D29="","","medium"))) -> hard
A30: floor pull | B30: =INDEX(Strength!$D$33:$D$37,MATCH(A30,s_cat_names,0)) -> Deadlift | C30: =INDEX(Strength!$E$33:$E$37,MATCH(A30,s_cat_names,0)) -> 0.047872031 | D30: =INDEX(s_cat_class,MATCH(A30,s_cat_names,0)) -> in line | E30: =IF(D30="weak","hard",IF(D30="strong","maintenance",IF(D30="","","medium"))) -> medium
A31: horizontal press | B31: =INDEX(Strength!$D$33:$D$37,MATCH(A31,s_cat_names,0)) -> Bench press | C31: =INDEX(Strength!$E$33:$E$37,MATCH(A31,s_cat_names,0)) -> -0.14647015 | D31: =INDEX(s_cat_class,MATCH(A31,s_cat_names,0)) -> weak | E31: =IF(D31="weak","hard",IF(D31="strong","maintenance",IF(D31="","","medium"))) -> hard
A32: vertical press | B32: =INDEX(Strength!$D$33:$D$37,MATCH(A32,s_cat_names,0)) -> Overhead press | C32: =INDEX(Strength!$E$33:$E$37,MATCH(A32,s_cat_names,0)) -> 0.12384388 | D32: =INDEX(s_cat_class,MATCH(A32,s_cat_names,0)) -> strong | E32: =IF(D32="weak","hard",IF(D32="strong","maintenance",IF(D32="","","medium"))) -> maintenance
A33: pull | B33: =INDEX(Strength!$D$33:$D$37,MATCH(A33,s_cat_names,0)) -> Chin-up | C33: =INDEX(Strength!$E$33:$E$37,MATCH(A33,s_cat_names,0)) -> 0.083706596 | D33: =INDEX(s_cat_class,MATCH(A33,s_cat_names,0)) -> in line | E33: =IF(D33="weak","hard",IF(D33="strong","maintenance",IF(D33="","","medium"))) -> medium
A35: 4. Body parts: where size gains pay most
A36: body part | B36: vs ideal ratio | C36: of Butt maximum | D36: size tier | E36: basis
A37: arm | B37: =IF(J37="","",IFERROR(INDEX(r_ratio_dev,MATCH(J37,r_ratio_keys,0)),"")) | C37: =INDEX(r_girth_att,MATCH("arm",r_girth_sites,0)) | D37: =IF(AND(NOT(ISNUMBER(B37)),NOT(ISNUMBER(C37))),"",IF(OR(AND(ISNUMBER(B37),B37<p_size_hard_dev),AND(ISNUMBER(C37),C37<p_size_hard_att)),"hard",IF(OR(AND(ISNUMBER(B37),B37<p_size_med_dev),AND(ISNUMBER(C37),C37<p_size_med_att)),"medium","maintenance"))) | E37: men: arm/wrist (Reeves); women: no ideal | J37: =IF(m_sex="female","","arm_wrist")
A38: forearm | B38: =IF(J38="","",IFERROR(INDEX(r_ratio_dev,MATCH(J38,r_ratio_keys,0)),"")) | C38: =INDEX(r_girth_att,MATCH("forearm",r_girth_sites,0)) | D38: =IF(AND(NOT(ISNUMBER(B38)),NOT(ISNUMBER(C38))),"",IF(OR(AND(ISNUMBER(B38),B38<p_size_hard_dev),AND(ISNUMBER(C38),C38<p_size_hard_att)),"hard",IF(OR(AND(ISNUMBER(B38),B38<p_size_med_dev),AND(ISNUMBER(C38),C38<p_size_med_att)),"medium","maintenance"))) | E38: men: forearm/wrist (McCallum); women: no ideal | J38: =IF(m_sex="female","","forearm_wrist")
A39: chest | B39: =IF(J39="","",IFERROR(INDEX(r_ratio_dev,MATCH(J39,r_ratio_keys,0)),"")) | C39: =INDEX(r_girth_att,MATCH("chest",r_girth_sites,0)) | D39: =IF(AND(NOT(ISNUMBER(B39)),NOT(ISNUMBER(C39))),"",IF(OR(AND(ISNUMBER(B39),B39<p_size_hard_dev),AND(ISNUMBER(C39),C39<p_size_hard_att)),"hard",IF(OR(AND(ISNUMBER(B39),B39<p_size_med_dev),AND(ISNUMBER(C39),C39<p_size_med_att)),"medium","maintenance"))) | E39: men: chest/wrist (McCallum); women: no ideal | J39: =IF(m_sex="female","","chest_wrist")
A40: shoulders | B40: =IF(J40="","",IFERROR(INDEX(r_ratio_dev,MATCH(J40,r_ratio_keys,0)),"")) -> 0.02 | D40: =IF(AND(NOT(ISNUMBER(B40)),NOT(ISNUMBER(C40))),"",IF(OR(AND(ISNUMBER(B40),B40<p_size_hard_dev),AND(ISNUMBER(C40),C40<p_size_hard_att)),"hard",IF(OR(AND(ISNUMBER(B40),B40<p_size_med_dev),AND(ISNUMBER(C40),C40<p_size_med_att)),"medium","maintenance"))) -> maintenance | E40: men: shoulders/chest (implied classical ideal); women: shoulders/hips = 1 | J40: =IF(m_sex="female","shoulders_hips","shoulders_chest") -> shoulders_hips
A41: thigh | B41: =IF(J41="","",IFERROR(INDEX(r_ratio_dev,MATCH(J41,r_ratio_keys,0)),"")) | C41: =INDEX(r_girth_att,MATCH("thigh",r_girth_sites,0)) | D41: =IF(AND(NOT(ISNUMBER(B41)),NOT(ISNUMBER(C41))),"",IF(OR(AND(ISNUMBER(B41),B41<p_size_hard_dev),AND(ISNUMBER(C41),C41<p_size_hard_att)),"hard",IF(OR(AND(ISNUMBER(B41),B41<p_size_med_dev),AND(ISNUMBER(C41),C41<p_size_med_att)),"medium","maintenance"))) | E41: men: thigh/knee (Reeves); women: no ideal | J41: =IF(m_sex="female","","thigh_knee")
A42: calf | B42: =IF(J42="","",IFERROR(INDEX(r_ratio_dev,MATCH(J42,r_ratio_keys,0)),"")) | C42: =INDEX(r_girth_att,MATCH("calf",r_girth_sites,0)) | D42: =IF(AND(NOT(ISNUMBER(B42)),NOT(ISNUMBER(C42))),"",IF(OR(AND(ISNUMBER(B42),B42<p_size_hard_dev),AND(ISNUMBER(C42),C42<p_size_hard_att)),"hard",IF(OR(AND(ISNUMBER(B42),B42<p_size_med_dev),AND(ISNUMBER(C42),C42<p_size_med_att)),"medium","maintenance"))) | E42: men: calf/ankle (Reeves); women: no ideal | J42: =IF(m_sex="female","","calf_ankle")
A43: neck | B43: =IF(J43="","",IFERROR(INDEX(r_ratio_dev,MATCH(J43,r_ratio_keys,0)),"")) | C43: =INDEX(r_girth_att,MATCH("neck",r_girth_sites,0)) | D43: =IF(AND(NOT(ISNUMBER(B43)),NOT(ISNUMBER(C43))),"",IF(OR(AND(ISNUMBER(B43),B43<p_size_hard_dev),AND(ISNUMBER(C43),C43<p_size_hard_att)),"hard",IF(OR(AND(ISNUMBER(B43),B43<p_size_med_dev),AND(ISNUMBER(C43),C43<p_size_med_att)),"medium","maintenance"))) | E43: men: neck/arm (Reeves); no exercises recommended | J43: =IF(m_sex="female","","neck_arm")
A44: hips | B44: =IF(J44="","",IFERROR(INDEX(r_ratio_dev,MATCH(J44,r_ratio_keys,0)),"")) -> -0.051490515 | D44: =IF(AND(NOT(ISNUMBER(B44)),NOT(ISNUMBER(C44))),"",IF(OR(AND(ISNUMBER(B44),B44<p_size_hard_dev),AND(ISNUMBER(C44),C44<p_size_hard_att)),"hard",IF(OR(AND(ISNUMBER(B44),B44<p_size_med_dev),AND(ISNUMBER(C44),C44<p_size_med_att)),"medium","maintenance"))) -> medium | E44: women: hips/height implied by waist/hip 0.70 at the leanness target; men: no ideal | J44: =IF(m_sex="female","hips_height","") -> hips_height
...

Sheet Parameters
A1: Scalar parameters
A2: key | B2: value | C2: unit | D2: meaning and source
A3: lr_tol_cm | B3: 1 | C3: cm | D3: Left/right difference treated as real. Tape repeatability is about 0.5 cm per reading, so a difference of two readings needs about 1 cm.
A4: whtr_limit | B4: 0.5 | C4: ratio | D4: Waist-to-height boundary ('keep your waist to less than half your height'), Ashwell & Gibson, BMJ Open 2016.
A5: butt_w | B5: 22.667 | D5: Casey Butt max lean mass (lb) = H^1.5 * (sqrt(W)/butt_w + sqrt(A)/butt_a) * (BF%/butt_bf + 1), inches. weightrainer.net/potential.html
A6: butt_a | B6: 17.0104 | D6: Casey Butt, ankle divisor
A7: butt_bf | B7: 224 | D7: Casey Butt, body-fat divisor (fitted on champions at about 4.5-14% fat)
A8: berkhan_offset | B8: 100 | C8: cm/kg | D8: Martin Berkhan: contest weight (kg) = height (cm) - 100. leangains.com/2010/12/maximum-muscular-potential.html
A9: berkhan_bf | B9: 0.05 | C9: fraction | D9: Body fat of Berkhan's contest condition (about 5%)
A10: ffmi_slope | B10: 6.1 | C10: kg/m2 per m | D10: FFMI height normalisation: FFMI + slope*(ref_h - height_m). Kouri et al. 1995.
A11: ffmi_ref_h | B11: 1.8 | C11: m | D11: FFMI reference height
A12: cm_per_in | B12: 2.54 | D12: Unit conversion (exact)
A13: kg_per_lb | B13: 0.45359237 | D13: Unit conversion (exact)
A14: wathan_a | B14: 48.8 | D14: Wathan 1RM: 1RM = 100*load / (a + b*exp(-k*reps)). Used by Symmetric Strength (LeSuer et al., JSCR 1997)
A15: wathan_b | B15: 53.8 | D15: Wathan, b
A16: wathan_k | B16: 0.075 | D16: Wathan, k
A17: dev_tol | B17: 0.1 | C17: fraction | D17: Deviation from the overall strength score treated as real. Judgment: 1RM estimates from sets under 10 reps are typically within about 5%, and lift ratios carry similar uncertainty
A18: rock_a | B18: 132.853 | D18: Rockport walk (Kline et al., Med Sci Sports Exerc 1987), men: VO2max = a - b*weight(lb) - c*age + d - e*time(min) - f*HR
A19: rock_b | B19: 0.0769 | D19: Rockport, weight (lb)
A20: rock_c | B20: 0.3877 | D20: Rockport, age
A21: rock_e | B21: 3.2649 | D21: Rockport, time (min)
A22: rock_f | B22: 0.1565 | D22: Rockport, heart rate (bpm)
A23: cooper_a | B23: 504.9 | C23: m | D23: Cooper 12-min run (Cooper, JAMA 1968): VO2max = (distance - a) / b
A24: cooper_b | B24: 44.73 | D24: Cooper, divisor
A25: vdot_a | B25: -4.6 | D25: Daniels-Gilbert VDOT: VO2(v) = a + b*v + c*v^2 (v in m/min); fraction(t) = d + e*exp(-f*t) + g*exp(-h*t); VDOT = VO2/fraction
A26: vdot_b | B26: 0.182258 | D26: VDOT
A27: vdot_c | B27: 0.000104 | D27: VDOT
A28: vdot_d | B28: 0.8 | D28: VDOT
A29: vdot_e | B29: 0.1894393 | D29: VDOT
A30: vdot_f | B30: 0.012778 | D30: VDOT
A31: vdot_g | B31: 0.2989558 | D31: VDOT
A32: vdot_h | B32: 0.1932605 | D32: VDOT
A33: cyc_a | B33: 10.8 | D33: ACSM leg-cycling equation: VO2 = a * W/kg + b. Built for steady submaximal work; at ramp-test peak it is an approximation
A34: cyc_b | B34: 7 | D34: ACSM cycling, resting + unloaded pedalling
A35: strength_ref | B35: 100 | C35: score | D35: Strength score treated as full attainment in the composite. Symmetric Strength: 100 is close to the drug-free limit for lifters under 40
A36: whtr_zero | B36: 0.6 | C36: ratio | D36: Waist-to-height at which the health score is 0 (Ashwell: 0.6 and above is the 'take action' band)
A37: whr_ideal | B37: 0.7 | C37: ratio | D37: Women: waist/hip ratio used for the hip ideal (Singh 1993 and later cross-cultural work; contested, see Read me)
A38: ffmi_alt_f | B38: 19.2 | C38: kg/m2 | D38: Women, alternative size ceiling: FFMI 19.2 (Symmetric Strength's estimate; 99.9th percentile of women 18-34, Schutz et al. 2002). Shown for comparison only
A39: whtr_best | B39: 0.45 | C39: ratio | D39: Waist-to-height at which the health score reaches 1. Judgment: middle of Ashwell's 0.4-0.5 healthy band; below 0.4 Ashwell advises 'take care'
A40: size_hard_dev | B40: -0.15 | C40: fraction | D40: Plan: a body part is 'hard' for size if its bone-anchored ratio is more than 15% below ideal...
...

Sheet Report
A1: Body assessment report
A2: Analysis date | B2: =MAX(Measurements!$E$1:$AH$1) -> 46266 | C2: Defaults to the latest dated column; overwrite with a date to analyse an earlier one.
A3: Date column found | B3: =MATCH(r_date,Measurements!$E$1:$AH$1,0) -> 1
A5: Measurements used
A6: key | B6: value | C6: unit
A7: height | B7: =IF(INDEX(Measurements!$E$2:$AH$69,MATCH("height",Measurements!$A$2:$A$69,0),r_col)="","",INDEX(Measurements!$E$2:$AH$69,MATCH("height",Measurements!$A$2:$A$69,0),r_col)) -> 164 | C7: cm
A8: weight | B8: =IF(INDEX(Measurements!$E$2:$AH$69,MATCH("weight",Measurements!$A$2:$A$69,0),r_col)="","",INDEX(Measurements!$E$2:$AH$69,MATCH("weight",Measurements!$A$2:$A$69,0),r_col)) -> 66 | C8: kg
A9: age | B9: =IF(INDEX(Measurements!$E$2:$AH$69,MATCH("age",Measurements!$A$2:$A$69,0),r_col)="","",INDEX(Measurements!$E$2:$AH$69,MATCH("age",Measurements!$A$2:$A$69,0),r_col)) -> 38 | C9: years
A10: sex | B10: =IF(INDEX(Measurements!$E$2:$AH$69,MATCH("sex",Measurements!$A$2:$A$69,0),r_col)="","",INDEX(Measurements!$E$2:$AH$69,MATCH("sex",Measurements!$A$2:$A$69,0),r_col)) -> female | C10: male/female
A11: neck | B11: =IF(INDEX(Measurements!$E$2:$AH$69,MATCH("neck",Measurements!$A$2:$A$69,0),r_col)="","",INDEX(Measurements!$E$2:$AH$69,MATCH("neck",Measurements!$A$2:$A$69,0),r_col)) -> 32 | C11: cm
A12: shoulders | B12: =IF(INDEX(Measurements!$E$2:$AH$69,MATCH("shoulders",Measurements!$A$2:$A$69,0),r_col)="","",INDEX(Measurements!$E$2:$AH$69,MATCH("shoulders",Measurements!$A$2:$A$69,0),r_col)) -> 102 | C12: cm
A13: chest | B13: =IF(INDEX(Measurements!$E$2:$AH$69,MATCH("chest",Measurements!$A$2:$A$69,0),r_col)="","",INDEX(Measurements!$E$2:$AH$69,MATCH("chest",Measurements!$A$2:$A$69,0),r_col)) -> 92 | C13: cm
A14: chest_relaxed | B14: =IF(INDEX(Measurements!$E$2:$AH$69,MATCH("chest_relaxed",Measurements!$A$2:$A$69,0),r_col)="","",INDEX(Measurements!$E$2:$AH$69,MATCH("chest_relaxed",Measurements!$A$2:$A$69,0),r_col)) -> 90 | C14: cm
A15: waist | B15: =IF(INDEX(Measurements!$E$2:$AH$69,MATCH("waist",Measurements!$A$2:$A$69,0),r_col)="","",INDEX(Measurements!$E$2:$AH$69,MATCH("waist",Measurements!$A$2:$A$69,0),r_col)) -> 76 | C15: cm
A16: hips | B16: =IF(INDEX(Measurements!$E$2:$AH$69,MATCH("hips",Measurements!$A$2:$A$69,0),r_col)="","",INDEX(Measurements!$E$2:$AH$69,MATCH("hips",Measurements!$A$2:$A$69,0),r_col)) -> 100 | C16: cm
A17: wrist_l | B17: =IF(INDEX(Measurements!$E$2:$AH$69,MATCH("wrist_l",Measurements!$A$2:$A$69,0),r_col)="","",INDEX(Measurements!$E$2:$AH$69,MATCH("wrist_l",Measurements!$A$2:$A$69,0),r_col)) -> 15 | C17: cm
A18: wrist_r | B18: =IF(INDEX(Measurements!$E$2:$AH$69,MATCH("wrist_r",Measurements!$A$2:$A$69,0),r_col)="","",INDEX(Measurements!$E$2:$AH$69,MATCH("wrist_r",Measurements!$A$2:$A$69,0),r_col)) -> 15 | C18: cm
A19: forearm_l | B19: =IF(INDEX(Measurements!$E$2:$AH$69,MATCH("forearm_l",Measurements!$A$2:$A$69,0),r_col)="","",INDEX(Measurements!$E$2:$AH$69,MATCH("forearm_l",Measurements!$A$2:$A$69,0),r_col)) -> 23.5 | C19: cm
A20: forearm_r | B20: =IF(INDEX(Measurements!$E$2:$AH$69,MATCH("forearm_r",Measurements!$A$2:$A$69,0),r_col)="","",INDEX(Measurements!$E$2:$AH$69,MATCH("forearm_r",Measurements!$A$2:$A$69,0),r_col)) -> 24 | C20: cm
A21: arm_l | B21: =IF(INDEX(Measurements!$E$2:$AH$69,MATCH("arm_l",Measurements!$A$2:$A$69,0),r_col)="","",INDEX(Measurements!$E$2:$AH$69,MATCH("arm_l",Measurements!$A$2:$A$69,0),r_col)) -> 28 | C21: cm
A22: arm_r | B22: =IF(INDEX(Measurements!$E$2:$AH$69,MATCH("arm_r",Measurements!$A$2:$A$69,0),r_col)="","",INDEX(Measurements!$E$2:$AH$69,MATCH("arm_r",Measurements!$A$2:$A$69,0),r_col)) -> 28.5 | C22: cm
A23: thigh_l | B23: =IF(INDEX(Measurements!$E$2:$AH$69,MATCH("thigh_l",Measurements!$A$2:$A$69,0),r_col)="","",INDEX(Measurements!$E$2:$AH$69,MATCH("thigh_l",Measurements!$A$2:$A$69,0),r_col)) -> 56 | C23: cm
A24: thigh_r | B24: =IF(INDEX(Measurements!$E$2:$AH$69,MATCH("thigh_r",Measurements!$A$2:$A$69,0),r_col)="","",INDEX(Measurements!$E$2:$AH$69,MATCH("thigh_r",Measurements!$A$2:$A$69,0),r_col)) -> 56.5 | C24: cm
A25: thigh_relaxed_l | B25: =IF(INDEX(Measurements!$E$2:$AH$69,MATCH("thigh_relaxed_l",Measurements!$A$2:$A$69,0),r_col)="","",INDEX(Measurements!$E$2:$AH$69,MATCH("thigh_relaxed_l",Measurements!$A$2:$A$69,0),r_col)) -> 54 | C25: cm
A26: thigh_relaxed_r | B26: =IF(INDEX(Measurements!$E$2:$AH$69,MATCH("thigh_relaxed_r",Measurements!$A$2:$A$69,0),r_col)="","",INDEX(Measurements!$E$2:$AH$69,MATCH("thigh_relaxed_r",Measurements!$A$2:$A$69,0),r_col)) -> 54.5 | C26: cm
A27: knee_l | B27: =IF(INDEX(Measurements!$E$2:$AH$69,MATCH("knee_l",Measurements!$A$2:$A$69,0),r_col)="","",INDEX(Measurements!$E$2:$AH$69,MATCH("knee_l",Measurements!$A$2:$A$69,0),r_col)) -> 36 | C27: cm
A28: knee_r | B28: =IF(INDEX(Measurements!$E$2:$AH$69,MATCH("knee_r",Measurements!$A$2:$A$69,0),r_col)="","",INDEX(Measurements!$E$2:$AH$69,MATCH("knee_r",Measurements!$A$2:$A$69,0),r_col)) -> 36 | C28: cm
A29: calf_l | B29: =IF(INDEX(Measurements!$E$2:$AH$69,MATCH("calf_l",Measurements!$A$2:$A$69,0),r_col)="","",INDEX(Measurements!$E$2:$AH$69,MATCH("calf_l",Measurements!$A$2:$A$69,0),r_col)) -> 36 | C29: cm
A30: calf_r | B30: =IF(INDEX(Measurements!$E$2:$AH$69,MATCH("calf_r",Measurements!$A$2:$A$69,0),r_col)="","",INDEX(Measurements!$E$2:$AH$69,MATCH("calf_r",Measurements!$A$2:$A$69,0),r_col)) -> 36.5 | C30: cm
A31: calf_relaxed_l | B31: =IF(INDEX(Measurements!$E$2:$AH$69,MATCH("calf_relaxed_l",Measurements!$A$2:$A$69,0),r_col)="","",INDEX(Measurements!$E$2:$AH$69,MATCH("calf_relaxed_l",Measurements!$A$2:$A$69,0),r_col)) -> 35 | C31: cm
A32: calf_relaxed_r | B32: =IF(INDEX(Measurements!$E$2:$AH$69,MATCH("calf_relaxed_r",Measurements!$A$2:$A$69,0),r_col)="","",INDEX(Measurements!$E$2:$AH$69,MATCH("calf_relaxed_r",Measurements!$A$2:$A$69,0),r_col)) -> 35.5 | C32: cm
A33: ankle_l | B33: =IF(INDEX(Measurements!$E$2:$AH$69,MATCH("ankle_l",Measurements!$A$2:$A$69,0),r_col)="","",INDEX(Measurements!$E$2:$AH$69,MATCH("ankle_l",Measurements!$A$2:$A$69,0),r_col)) -> 21 | C33: cm
A34: ankle_r | B34: =IF(INDEX(Measurements!$E$2:$AH$69,MATCH("ankle_r",Measurements!$A$2:$A$69,0),r_col)="","",INDEX(Measurements!$E$2:$AH$69,MATCH("ankle_r",Measurements!$A$2:$A$69,0),r_col)) -> 21 | C34: cm
A35: wrist | B35: =IF(COUNT(m_wrist_l,m_wrist_r)=0,"",AVERAGE(m_wrist_l,m_wrist_r)) -> 15 | C35: cm, mean L/R
A36: forearm | B36: =IF(COUNT(m_forearm_l,m_forearm_r)=0,"",AVERAGE(m_forearm_l,m_forearm_r)) -> 23.75 | C36: cm, mean L/R
A37: arm | B37: =IF(COUNT(m_arm_l,m_arm_r)=0,"",AVERAGE(m_arm_l,m_arm_r)) -> 28.25 | C37: cm, mean L/R
A38: thigh | B38: =IF(COUNT(m_thigh_l,m_thigh_r)=0,"",AVERAGE(m_thigh_l,m_thigh_r)) -> 56.25 | C38: cm, mean L/R
A39: thigh_relaxed | B39: =IF(COUNT(m_thigh_relaxed_l,m_thigh_relaxed_r)=0,"",AVERAGE(m_thigh_relaxed_l,m_thigh_relaxed_r)) -> 54.25 | C39: cm, mean L/R
A40: knee | B40: =IF(COUNT(m_knee_l,m_knee_r)=0,"",AVERAGE(m_knee_l,m_knee_r)) -> 36 | C40: cm, mean L/R
A41: calf | B41: =IF(COUNT(m_calf_l,m_calf_r)=0,"",AVERAGE(m_calf_l,m_calf_r)) -> 36.25 | C41: cm, mean L/R
...

Sheet Strength
A1: Strength assessment (Symmetric Strength method)
A2: Analysis date | B2: =r_date -> 46266
A3: Bodyweight (kg) | B3: =m_weight -> 66
A4: Age | B4: =m_age -> 38
A5: Age coefficient | B5: =INDEX(t_agecoef,MATCH(MIN(90,MAX(14,INT(m_age))),t_ages,0)) -> 1
A6: Wilks coefficient | B6: =500/(p_wilks_a+p_wilks_b*m_weight+p_wilks_c*m_weight^2+p_wilks_d*m_weight^3+p_wilks_e*m_weight^4+p_wilks_f*m_weight^5) -> 1.037374
A7: Powerlifting total per kg of deadlift | B7: =1+pl_ratio_squat+pl_ratio_bench -> 2.41
A8: Score per kg of deadlift-equivalent | B8: =s_plsum*s_wilks/4*s_agec -> 0.62501785 | C8: A lift's score = 1/4 of the age-adjusted Wilks of the total you would have if every lift matched it
A10: Lifts
A11: lift | B11: category | C11: load entered | D11: reps | E11: total load (kg) | F11: est. 1RM (kg) | G11: est. 1RM, added weight (bodyweight lifts) | H11: deadlift equiv. (kg) | I11: score | J11: tier | K11: vs overall | L11: class | M11: note | N11: _score | O11: _entered | P11: _cat|score
A12: =Parameters!$B$196 -> Back squat | B12: =Parameters!$C$196 -> squat | C12: =IF(INDEX(Measurements!$E$2:$AH$69,MATCH("squat_load",Measurements!$A$2:$A$69,0),r_col)="","",INDEX(Measurements!$E$2:$AH$69,MATCH("squat_load",Measurements!$A$2:$A$69,0),r_col)) -> 50 | D12: =IF(INDEX(Measurements!$E$2:$AH$69,MATCH("squat_reps",Measurements!$A$2:$A$69,0),r_col)="","",INT(INDEX(Measurements!$E$2:$AH$69,MATCH("squat_reps",Measurements!$A$2:$A$69,0),r_col))) -> 5 | E12: =IF(OR(C12="",D12=""),"",C12+IF(Parameters!$D$196=1,m_weight,0)) -> 50 | F12: =IF(E12="","",E12*100/(p_wathan_a+p_wathan_b*EXP(-p_wathan_k*D12))) -> 58.291253 | G12: =IF(F12="","",F12-IF(Parameters!$D$196=1,m_weight,0)) -> 58.291253 | H12: =IF(F12="","",IF((F12/Parameters!$F$196-Parameters!$AC$196*m_weight)/IF(Parameters!$E$196="",1,INDEX(Parameters!$G$196:$G$212,MATCH(Parameters!$E$196,Parameters!$A$196:$A$212,0)))<=0,"",(F12/Parameters!$F$196-Parameters!$AC$196*m_weight)/IF(Parameters!$E$196="",1,INDEX(Parameters!$G$196:$G$212,MATCH(Parameters!$E$196,Parameters!$A$196:$A$212,0))))) -> 69.394348 | I12: =IF(H12="","",H12*s_perkg) -> 43.372706 | J12: =IF(I12="","",INDEX(t_names,MATCH(I12,t_mins,1))) -> Untrained | K12: =IF(I12="","",I12/s_overall-1) -> -0.10895235 | L12: =IF(K12="","",IF(K12>p_dev_tol,"strong",IF(K12<-p_dev_tol,"weak","in line"))) -> weak | M12: =IF(AND(F12<>"",H12=""),"below the conversion's range: not scored","") | N12: =IF(I12="",0,I12) -> 43.372706 | O12: =IF(I12="",0,1) -> 1 | P12: =IF(I12="","",B12&"|"&I12) -> squat|43.3727061701956
A13: =Parameters!$B$197 -> Front squat | B13: =Parameters!$C$197 -> squat | C13: =IF(INDEX(Measurements!$E$2:$AH$69,MATCH("front_squat_load",Measurements!$A$2:$A$69,0),r_col)="","",INDEX(Measurements!$E$2:$AH$69,MATCH("front_squat_load",Measurements!$A$2:$A$69,0),r_col)) | D13: =IF(INDEX(Measurements!$E$2:$AH$69,MATCH("front_squat_reps",Measurements!$A$2:$A$69,0),r_col)="","",INT(INDEX(Measurements!$E$2:$AH$69,MATCH("front_squat_reps",Measurements!$A$2:$A$69,0),r_col))) | E13: =IF(OR(C13="",D13=""),"",C13+IF(Parameters!$D$197=1,m_weight,0)) | F13: =IF(E13="","",E13*100/(p_wathan_a+p_wathan_b*EXP(-p_wathan_k*D13))) | G13: =IF(F13="","",F13-IF(Parameters!$D$197=1,m_weight,0)) | H13: =IF(F13="","",IF((F13/Parameters!$F$197-Parameters!$AC$197*m_weight)/IF(Parameters!$E$197="",1,INDEX(Parameters!$G$196:$G$212,MATCH(Parameters!$E$197,Parameters!$A$196:$A$212,0)))<=0,"",(F13/Parameters!$F$197-Parameters!$AC$197*m_weight)/IF(Parameters!$E$197="",1,INDEX(Parameters!$G$196:$G$212,MATCH(Parameters!$E$197,Parameters!$A$196:$A$212,0))))) | I13: =IF(H13="","",H13*s_perkg) | J13: =IF(I13="","",INDEX(t_names,MATCH(I13,t_mins,1))) | K13: =IF(I13="","",I13/s_overall-1) | L13: =IF(K13="","",IF(K13>p_dev_tol,"strong",IF(K13<-p_dev_tol,"weak","in line"))) | M13: =IF(AND(F13<>"",H13=""),"below the conversion's range: not scored","") | N13: =IF(I13="",0,I13) -> 0 | O13: =IF(I13="",0,1) -> 0 | P13: =IF(I13="","",B13&"|"&I13)
A14: =Parameters!$B$198 -> 45-degree leg press | B14: =Parameters!$C$198 -> squat | C14: =IF(INDEX(Measurements!$E$2:$AH$69,MATCH("leg_press_load",Measurements!$A$2:$A$69,0),r_col)="","",INDEX(Measurements!$E$2:$AH$69,MATCH("leg_press_load",Measurements!$A$2:$A$69,0),r_col)) -> 120 | D14: =IF(INDEX(Measurements!$E$2:$AH$69,MATCH("leg_press_reps",Measurements!$A$2:$A$69,0),r_col)="","",INT(INDEX(Measurements!$E$2:$AH$69,MATCH("leg_press_reps",Measurements!$A$2:$A$69,0),r_col))) -> 10 | E14: =IF(OR(C14="",D14=""),"",C14+IF(Parameters!$D$198=1,m_weight,0)) -> 120 | F14: =IF(E14="","",E14*100/(p_wathan_a+p_wathan_b*EXP(-p_wathan_k*D14))) -> 161.69604 | G14: =IF(F14="","",F14-IF(Parameters!$D$198=1,m_weight,0)) -> 161.69604 | H14: =IF(F14="","",IF((F14/Parameters!$F$198-Parameters!$AC$198*m_weight)/IF(Parameters!$E$198="",1,INDEX(Parameters!$G$196:$G$212,MATCH(Parameters!$E$198,Parameters!$A$196:$A$212,0)))<=0,"",(F14/Parameters!$F$198-Parameters!$AC$198*m_weight)/IF(Parameters!$E$198="",1,INDEX(Parameters!$G$196:$G$212,MATCH(Parameters!$E$198,Parameters!$A$196:$A$212,0))))) -> 58.925204 | I14: =IF(H14="","",H14*s_perkg) -> 36.829304 | J14: =IF(I14="","",INDEX(t_names,MATCH(I14,t_mins,1))) -> Untrained | K14: =IF(I14="","",I14/s_overall-1) -> -0.24337983 | L14: =IF(K14="","",IF(K14>p_dev_tol,"strong",IF(K14<-p_dev_tol,"weak","in line"))) -> weak | M14: =IF(AND(F14<>"",H14=""),"below the conversion's range: not scored","") | N14: =IF(I14="",0,I14) -> 36.829304 | O14: =IF(I14="",0,1) -> 1 | P14: =IF(I14="","",B14&"|"&I14) -> squat|36.829303813568
A15: =Parameters!$B$199 -> Deadlift | B15: =Parameters!$C$199 -> floor pull | C15: =IF(INDEX(Measurements!$E$2:$AH$69,MATCH("deadlift_load",Measurements!$A$2:$A$69,0),r_col)="","",INDEX(Measurements!$E$2:$AH$69,MATCH("deadlift_load",Measurements!$A$2:$A$69,0),r_col)) -> 70 | D15: =IF(INDEX(Measurements!$E$2:$AH$69,MATCH("deadlift_reps",Measurements!$A$2:$A$69,0),r_col)="","",INT(INDEX(Measurements!$E$2:$AH$69,MATCH("deadlift_reps",Measurements!$A$2:$A$69,0),r_col))) -> 5 | E15: =IF(OR(C15="",D15=""),"",C15+IF(Parameters!$D$199=1,m_weight,0)) -> 70 | F15: =IF(E15="","",E15*100/(p_wathan_a+p_wathan_b*EXP(-p_wathan_k*D15))) -> 81.607754 | G15: =IF(F15="","",F15-IF(Parameters!$D$199=1,m_weight,0)) -> 81.607754 | H15: =IF(F15="","",IF((F15/Parameters!$F$199-Parameters!$AC$199*m_weight)/IF(Parameters!$E$199="",1,INDEX(Parameters!$G$196:$G$212,MATCH(Parameters!$E$199,Parameters!$A$196:$A$212,0)))<=0,"",(F15/Parameters!$F$199-Parameters!$AC$199*m_weight)/IF(Parameters!$E$199="",1,INDEX(Parameters!$G$196:$G$212,MATCH(Parameters!$E$199,Parameters!$A$196:$A$212,0))))) -> 81.607754 | I15: =IF(H15="","",H15*s_perkg) -> 51.006302 | J15: =IF(I15="","",INDEX(t_names,MATCH(I15,t_mins,1))) -> Novice | K15: =IF(I15="","",I15/s_overall-1) -> 0.047872031 | L15: =IF(K15="","",IF(K15>p_dev_tol,"strong",IF(K15<-p_dev_tol,"weak","in line"))) -> in line | M15: =IF(AND(F15<>"",H15=""),"below the conversion's range: not scored","") | N15: =IF(I15="",0,I15) -> 51.006302 | O15: =IF(I15="",0,1) -> 1 | P15: =IF(I15="","",B15&"|"&I15) -> floor pull|51.00630245615
A16: =Parameters!$B$200 -> Sumo deadlift | B16: =Parameters!$C$200 -> floor pull | C16: =IF(INDEX(Measurements!$E$2:$AH$69,MATCH("sumo_deadlift_load",Measurements!$A$2:$A$69,0),r_col)="","",INDEX(Measurements!$E$2:$AH$69,MATCH("sumo_deadlift_load",Measurements!$A$2:$A$69,0),r_col)) | D16: =IF(INDEX(Measurements!$E$2:$AH$69,MATCH("sumo_deadlift_reps",Measurements!$A$2:$A$69,0),r_col)="","",INT(INDEX(Measurements!$E$2:$AH$69,MATCH("sumo_deadlift_reps",Measurements!$A$2:$A$69,0),r_col))) | E16: =IF(OR(C16="",D16=""),"",C16+IF(Parameters!$D$200=1,m_weight,0)) | F16: =IF(E16="","",E16*100/(p_wathan_a+p_wathan_b*EXP(-p_wathan_k*D16))) | G16: =IF(F16="","",F16-IF(Parameters!$D$200=1,m_weight,0)) | H16: =IF(F16="","",IF((F16/Parameters!$F$200-Parameters!$AC$200*m_weight)/IF(Parameters!$E$200="",1,INDEX(Parameters!$G$196:$G$212,MATCH(Parameters!$E$200,Parameters!$A$196:$A$212,0)))<=0,"",(F16/Parameters!$F$200-Parameters!$AC$200*m_weight)/IF(Parameters!$E$200="",1,INDEX(Parameters!$G$196:$G$212,MATCH(Parameters!$E$200,Parameters!$A$196:$A$212,0))))) | I16: =IF(H16="","",H16*s_perkg) | J16: =IF(I16="","",INDEX(t_names,MATCH(I16,t_mins,1))) | K16: =IF(I16="","",I16/s_overall-1) | L16: =IF(K16="","",IF(K16>p_dev_tol,"strong",IF(K16<-p_dev_tol,"weak","in line"))) | M16: =IF(AND(F16<>"",H16=""),"below the conversion's range: not scored","") | N16: =IF(I16="",0,I16) -> 0 | O16: =IF(I16="",0,1) -> 0 | P16: =IF(I16="","",B16&"|"&I16)
A17: =Parameters!$B$201 -> Power clean | B17: =Parameters!$C$201 -> floor pull | C17: =IF(INDEX(Measurements!$E$2:$AH$69,MATCH("power_clean_load",Measurements!$A$2:$A$69,0),r_col)="","",INDEX(Measurements!$E$2:$AH$69,MATCH("power_clean_load",Measurements!$A$2:$A$69,0),r_col)) | D17: =IF(INDEX(Measurements!$E$2:$AH$69,MATCH("power_clean_reps",Measurements!$A$2:$A$69,0),r_col)="","",INT(INDEX(Measurements!$E$2:$AH$69,MATCH("power_clean_reps",Measurements!$A$2:$A$69,0),r_col))) | E17: =IF(OR(C17="",D17=""),"",C17+IF(Parameters!$D$201=1,m_weight,0)) | F17: =IF(E17="","",E17*100/(p_wathan_a+p_wathan_b*EXP(-p_wathan_k*D17))) | G17: =IF(F17="","",F17-IF(Parameters!$D$201=1,m_weight,0)) | H17: =IF(F17="","",IF((F17/Parameters!$F$201-Parameters!$AC$201*m_weight)/IF(Parameters!$E$201="",1,INDEX(Parameters!$G$196:$G$212,MATCH(Parameters!$E$201,Parameters!$A$196:$A$212,0)))<=0,"",(F17/Parameters!$F$201-Parameters!$AC$201*m_weight)/IF(Parameters!$E$201="",1,INDEX(Parameters!$G$196:$G$212,MATCH(Parameters!$E$201,Parameters!$A$196:$A$212,0))))) | I17: =IF(H17="","",H17*s_perkg) | J17: =IF(I17="","",INDEX(t_names,MATCH(I17,t_mins,1))) | K17: =IF(I17="","",I17/s_overall-1) | L17: =IF(K17="","",IF(K17>p_dev_tol,"strong",IF(K17<-p_dev_tol,"weak","in line"))) | M17: =IF(AND(F17<>"",H17=""),"below the conversion's range: not scored","") | N17: =IF(I17="",0,I17) -> 0 | O17: =IF(I17="",0,1) -> 0 | P17: =IF(I17="","",B17&"|"&I17)
A18: =Parameters!$B$202 -> Bench press | B18: =Parameters!$C$202 -> horizontal press | C18: =IF(INDEX(Measurements!$E$2:$AH$69,MATCH("bench_load",Measurements!$A$2:$A$69,0),r_col)="","",INDEX(Measurements!$E$2:$AH$69,MATCH("bench_load",Measurements!$A$2:$A$69,0),r_col)) -> 32.5 | D18: =IF(INDEX(Measurements!$E$2:$AH$69,MATCH("bench_reps",Measurements!$A$2:$A$69,0),r_col)="","",INT(INDEX(Measurements!$E$2:$AH$69,MATCH("bench_reps",Measurements!$A$2:$A$69,0),r_col))) -> 5 | E18: =IF(OR(C18="",D18=""),"",C18+IF(Parameters!$D$202=1,m_weight,0)) -> 32.5 | F18: =IF(E18="","",E18*100/(p_wathan_a+p_wathan_b*EXP(-p_wathan_k*D18))) -> 37.889314 | G18: =IF(F18="","",F18-IF(Parameters!$D$202=1,m_weight,0)) -> 37.889314 | H18: =IF(F18="","",IF((F18/Parameters!$F$202-Parameters!$AC$202*m_weight)/IF(Parameters!$E$202="",1,INDEX(Parameters!$G$196:$G$212,MATCH(Parameters!$E$202,Parameters!$A$196:$A$212,0)))<=0,"",(F18/Parameters!$F$202-Parameters!$AC$202*m_weight)/IF(Parameters!$E$202="",1,INDEX(Parameters!$G$196:$G$212,MATCH(Parameters!$E$202,Parameters!$A$196:$A$212,0))))) -> 66.472481 | I18: =IF(H18="","",H18*s_perkg) -> 41.546487 | J18: =IF(I18="","",INDEX(t_names,MATCH(I18,t_mins,1))) -> Untrained | K18: =IF(I18="","",I18/s_overall-1) -> -0.14647015 | L18: =IF(K18="","",IF(K18>p_dev_tol,"strong",IF(K18<-p_dev_tol,"weak","in line"))) -> weak | M18: =IF(AND(F18<>"",H18=""),"below the conversion's range: not scored","") | N18: =IF(I18="",0,I18) -> 41.546487 | O18: =IF(I18="",0,1) -> 1 | P18: =IF(I18="","",B18&"|"&I18) -> horizontal press|41.5464869630295
A19: =Parameters!$B$203 -> Incline bench press | B19: =Parameters!$C$203 -> horizontal press | C19: =IF(INDEX(Measurements!$E$2:$AH$69,MATCH("incline_bench_load",Measurements!$A$2:$A$69,0),r_col)="","",INDEX(Measurements!$E$2:$AH$69,MATCH("incline_bench_load",Measurements!$A$2:$A$69,0),r_col)) | D19: =IF(INDEX(Measurements!$E$2:$AH$69,MATCH("incline_bench_reps",Measurements!$A$2:$A$69,0),r_col)="","",INT(INDEX(Measurements!$E$2:$AH$69,MATCH("incline_bench_reps",Measurements!$A$2:$A$69,0),r_col))) | E19: =IF(OR(C19="",D19=""),"",C19+IF(Parameters!$D$203=1,m_weight,0)) | F19: =IF(E19="","",E19*100/(p_wathan_a+p_wathan_b*EXP(-p_wathan_k*D19))) | G19: =IF(F19="","",F19-IF(Parameters!$D$203=1,m_weight,0)) | H19: =IF(F19="","",IF((F19/Parameters!$F$203-Parameters!$AC$203*m_weight)/IF(Parameters!$E$203="",1,INDEX(Parameters!$G$196:$G$212,MATCH(Parameters!$E$203,Parameters!$A$196:$A$212,0)))<=0,"",(F19/Parameters!$F$203-Parameters!$AC$203*m_weight)/IF(Parameters!$E$203="",1,INDEX(Parameters!$G$196:$G$212,MATCH(Parameters!$E$203,Parameters!$A$196:$A$212,0))))) | I19: =IF(H19="","",H19*s_perkg) | J19: =IF(I19="","",INDEX(t_names,MATCH(I19,t_mins,1))) | K19: =IF(I19="","",I19/s_overall-1) | L19: =IF(K19="","",IF(K19>p_dev_tol,"strong",IF(K19<-p_dev_tol,"weak","in line"))) | M19: =IF(AND(F19<>"",H19=""),"below the conversion's range: not scored","") | N19: =IF(I19="",0,I19) -> 0 | O19: =IF(I19="",0,1) -> 0 | P19: =IF(I19="","",B19&"|"&I19)
A20: =Parameters!$B$204 -> Dip | B20: =Parameters!$C$204 -> horizontal press | C20: =IF(INDEX(Measurements!$E$2:$AH$69,MATCH("dip_load",Measurements!$A$2:$A$69,0),r_col)="","",INDEX(Measurements!$E$2:$AH$69,MATCH("dip_load",Measurements!$A$2:$A$69,0),r_col)) | D20: =IF(INDEX(Measurements!$E$2:$AH$69,MATCH("dip_reps",Measurements!$A$2:$A$69,0),r_col)="","",INT(INDEX(Measurements!$E$2:$AH$69,MATCH("dip_reps",Measurements!$A$2:$A$69,0),r_col))) | E20: =IF(OR(C20="",D20=""),"",C20+IF(Parameters!$D$204=1,m_weight,0)) | F20: =IF(E20="","",E20*100/(p_wathan_a+p_wathan_b*EXP(-p_wathan_k*D20))) | G20: =IF(F20="","",F20-IF(Parameters!$D$204=1,m_weight,0)) | H20: =IF(F20="","",IF((F20/Parameters!$F$204-Parameters!$AC$204*m_weight)/IF(Parameters!$E$204="",1,INDEX(Parameters!$G$196:$G$212,MATCH(Parameters!$E$204,Parameters!$A$196:$A$212,0)))<=0,"",(F20/Parameters!$F$204-Parameters!$AC$204*m_weight)/IF(Parameters!$E$204="",1,INDEX(Parameters!$G$196:$G$212,MATCH(Parameters!$E$204,Parameters!$A$196:$A$212,0))))) | I20: =IF(H20="","",H20*s_perkg) | J20: =IF(I20="","",INDEX(t_names,MATCH(I20,t_mins,1))) | K20: =IF(I20="","",I20/s_overall-1) | L20: =IF(K20="","",IF(K20>p_dev_tol,"strong",IF(K20<-p_dev_tol,"weak","in line"))) | M20: =IF(AND(F20<>"",H20=""),"below the conversion's range: not scored","") | N20: =IF(I20="",0,I20) -> 0 | O20: =IF(I20="",0,1) -> 0 | P20: =IF(I20="","",B20&"|"&I20)
A21: =Parameters!$B$205 -> Overhead press | B21: =Parameters!$C$205 -> vertical press | C21: =IF(INDEX(Measurements!$E$2:$AH$69,MATCH("ohp_load",Measurements!$A$2:$A$69,0),r_col)="","",INDEX(Measurements!$E$2:$AH$69,MATCH("ohp_load",Measurements!$A$2:$A$69,0),r_col)) -> 25 | D21: =IF(INDEX(Measurements!$E$2:$AH$69,MATCH("ohp_reps",Measurements!$A$2:$A$69,0),r_col)="","",INT(INDEX(Measurements!$E$2:$AH$69,MATCH("ohp_reps",Measurements!$A$2:$A$69,0),r_col))) -> 5 | E21: =IF(OR(C21="",D21=""),"",C21+IF(Parameters!$D$205=1,m_weight,0)) -> 25 | F21: =IF(E21="","",E21*100/(p_wathan_a+p_wathan_b*EXP(-p_wathan_k*D21))) -> 29.145626 | G21: =IF(F21="","",F21-IF(Parameters!$D$205=1,m_weight,0)) -> 29.145626 | H21: =IF(F21="","",IF((F21/Parameters!$F$205-Parameters!$AC$205*m_weight)/IF(Parameters!$E$205="",1,INDEX(Parameters!$G$196:$G$212,MATCH(Parameters!$E$205,Parameters!$A$196:$A$212,0)))<=0,"",(F21/Parameters!$F$205-Parameters!$AC$205*m_weight)/IF(Parameters!$E$205="",1,INDEX(Parameters!$G$196:$G$212,MATCH(Parameters!$E$205,Parameters!$A$196:$A$212,0))))) -> 87.524403 | I21: =IF(H21="","",H21*s_perkg) -> 54.704314 | J21: =IF(I21="","",INDEX(t_names,MATCH(I21,t_mins,1))) -> Novice | K21: =IF(I21="","",I21/s_overall-1) -> 0.12384388 | L21: =IF(K21="","",IF(K21>p_dev_tol,"strong",IF(K21<-p_dev_tol,"weak","in line"))) -> strong | M21: =IF(AND(F21<>"",H21=""),"below the conversion's range: not scored","") | N21: =IF(I21="",0,I21) -> 54.704314 | O21: =IF(I21="",0,1) -> 1 | P21: =IF(I21="","",B21&"|"&I21) -> vertical press|54.704314088535
A22: =Parameters!$B$206 -> Push press | B22: =Parameters!$C$206 -> vertical press | C22: =IF(INDEX(Measurements!$E$2:$AH$69,MATCH("push_press_load",Measurements!$A$2:$A$69,0),r_col)="","",INDEX(Measurements!$E$2:$AH$69,MATCH("push_press_load",Measurements!$A$2:$A$69,0),r_col)) | D22: =IF(INDEX(Measurements!$E$2:$AH$69,MATCH("push_press_reps",Measurements!$A$2:$A$69,0),r_col)="","",INT(INDEX(Measurements!$E$2:$AH$69,MATCH("push_press_reps",Measurements!$A$2:$A$69,0),r_col))) | E22: =IF(OR(C22="",D22=""),"",C22+IF(Parameters!$D$206=1,m_weight,0)) | F22: =IF(E22="","",E22*100/(p_wathan_a+p_wathan_b*EXP(-p_wathan_k*D22))) | G22: =IF(F22="","",F22-IF(Parameters!$D$206=1,m_weight,0)) | H22: =IF(F22="","",IF((F22/Parameters!$F$206-Parameters!$AC$206*m_weight)/IF(Parameters!$E$206="",1,INDEX(Parameters!$G$196:$G$212,MATCH(Parameters!$E$206,Parameters!$A$196:$A$212,0)))<=0,"",(F22/Parameters!$F$206-Parameters!$AC$206*m_weight)/IF(Parameters!$E$206="",1,INDEX(Parameters!$G$196:$G$212,MATCH(Parameters!$E$206,Parameters!$A$196:$A$212,0))))) | I22: =IF(H22="","",H22*s_perkg) | J22: =IF(I22="","",INDEX(t_names,MATCH(I22,t_mins,1))) | K22: =IF(I22="","",I22/s_overall-1) | L22: =IF(K22="","",IF(K22>p_dev_tol,"strong",IF(K22<-p_dev_tol,"weak","in line"))) | M22: =IF(AND(F22<>"",H22=""),"below the conversion's range: not scored","") | N22: =IF(I22="",0,I22) -> 0 | O22: =IF(I22="",0,1) -> 0 | P22: =IF(I22="","",B22&"|"&I22)
A23: =Parameters!$B$207 -> Snatch press | B23: =Parameters!$C$207 -> vertical press | C23: =IF(INDEX(Measurements!$E$2:$AH$69,MATCH("snatch_press_load",Measurements!$A$2:$A$69,0),r_col)="","",INDEX(Measurements!$E$2:$AH$69,MATCH("snatch_press_load",Measurements!$A$2:$A$69,0),r_col)) | D23: =IF(INDEX(Measurements!$E$2:$AH$69,MATCH("snatch_press_reps",Measurements!$A$2:$A$69,0),r_col)="","",INT(INDEX(Measurements!$E$2:$AH$69,MATCH("snatch_press_reps",Measurements!$A$2:$A$69,0),r_col))) | E23: =IF(OR(C23="",D23=""),"",C23+IF(Parameters!$D$207=1,m_weight,0)) | F23: =IF(E23="","",E23*100/(p_wathan_a+p_wathan_b*EXP(-p_wathan_k*D23))) | G23: =IF(F23="","",F23-IF(Parameters!$D$207=1,m_weight,0)) | H23: =IF(F23="","",IF((F23/Parameters!$F$207-Parameters!$AC$207*m_weight)/IF(Parameters!$E$207="",1,INDEX(Parameters!$G$196:$G$212,MATCH(Parameters!$E$207,Parameters!$A$196:$A$212,0)))<=0,"",(F23/Parameters!$F$207-Parameters!$AC$207*m_weight)/IF(Parameters!$E$207="",1,INDEX(Parameters!$G$196:$G$212,MATCH(Parameters!$E$207,Parameters!$A$196:$A$212,0))))) | I23: =IF(H23="","",H23*s_perkg) | J23: =IF(I23="","",INDEX(t_names,MATCH(I23,t_mins,1))) | K23: =IF(I23="","",I23/s_overall-1) | L23: =IF(K23="","",IF(K23>p_dev_tol,"strong",IF(K23<-p_dev_tol,"weak","in line"))) | M23: =IF(AND(F23<>"",H23=""),"below the conversion's range: not scored","") | N23: =IF(I23="",0,I23) -> 0 | O23: =IF(I23="",0,1) -> 0 | P23: =IF(I23="","",B23&"|"&I23)
A24: =Parameters!$B$208 -> Chin-up | B24: =Parameters!$C$208 -> pull | C24: =IF(INDEX(Measurements!$E$2:$AH$69,MATCH("chin_up_load",Measurements!$A$2:$A$69,0),r_col)="","",INDEX(Measurements!$E$2:$AH$69,MATCH("chin_up_load",Measurements!$A$2:$A$69,0),r_col)) -> -30 | D24: =IF(INDEX(Measurements!$E$2:$AH$69,MATCH("chin_up_reps",Measurements!$A$2:$A$69,0),r_col)="","",INT(INDEX(Measurements!$E$2:$AH$69,MATCH("chin_up_reps",Measurements!$A$2:$A$69,0),r_col))) -> 5 | E24: =IF(OR(C24="",D24=""),"",C24+IF(Parameters!$D$208=1,m_weight,0)) -> 36 | F24: =IF(E24="","",E24*100/(p_wathan_a+p_wathan_b*EXP(-p_wathan_k*D24))) -> 41.969702 | G24: =IF(F24="","",F24-IF(Parameters!$D$208=1,m_weight,0)) -> -24.030298 | H24: =IF(F24="","",IF((F24/Parameters!$F$208-Parameters!$AC$208*m_weight)/IF(Parameters!$E$208="",1,INDEX(Parameters!$G$196:$G$212,MATCH(Parameters!$E$208,Parameters!$A$196:$A$212,0)))<=0,"",(F24/Parameters!$F$208-Parameters!$AC$208*m_weight)/IF(Parameters!$E$208="",1,INDEX(Parameters!$G$196:$G$212,MATCH(Parameters!$E$208,Parameters!$A$196:$A$212,0))))) -> 84.398532 | I24: =IF(H24="","",H24*s_perkg) -> 52.750589 | J24: =IF(I24="","",INDEX(t_names,MATCH(I24,t_mins,1))) -> Novice | K24: =IF(I24="","",I24/s_overall-1) -> 0.083706596 | L24: =IF(K24="","",IF(K24>p_dev_tol,"strong",IF(K24<-p_dev_tol,"weak","in line"))) -> in line | M24: =IF(AND(F24<>"",H24=""),"below the conversion's range: not scored","") | N24: =IF(I24="",0,I24) -> 52.750589 | O24: =IF(I24="",0,1) -> 1 | P24: =IF(I24="","",B24&"|"&I24) -> pull|52.750588585373
A25: =Parameters!$B$209 -> Pull-up | B25: =Parameters!$C$209 -> pull | C25: =IF(INDEX(Measurements!$E$2:$AH$69,MATCH("pull_up_load",Measurements!$A$2:$A$69,0),r_col)="","",INDEX(Measurements!$E$2:$AH$69,MATCH("pull_up_load",Measurements!$A$2:$A$69,0),r_col)) | D25: =IF(INDEX(Measurements!$E$2:$AH$69,MATCH("pull_up_reps",Measurements!$A$2:$A$69,0),r_col)="","",INT(INDEX(Measurements!$E$2:$AH$69,MATCH("pull_up_reps",Measurements!$A$2:$A$69,0),r_col))) | E25: =IF(OR(C25="",D25=""),"",C25+IF(Parameters!$D$209=1,m_weight,0)) | F25: =IF(E25="","",E25*100/(p_wathan_a+p_wathan_b*EXP(-p_wathan_k*D25))) | G25: =IF(F25="","",F25-IF(Parameters!$D$209=1,m_weight,0)) | H25: =IF(F25="","",IF((F25/Parameters!$F$209-Parameters!$AC$209*m_weight)/IF(Parameters!$E$209="",1,INDEX(Parameters!$G$196:$G$212,MATCH(Parameters!$E$209,Parameters!$A$196:$A$212,0)))<=0,"",(F25/Parameters!$F$209-Parameters!$AC$209*m_weight)/IF(Parameters!$E$209="",1,INDEX(Parameters!$G$196:$G$212,MATCH(Parameters!$E$209,Parameters!$A$196:$A$212,0))))) | I25: =IF(H25="","",H25*s_perkg) | J25: =IF(I25="","",INDEX(t_names,MATCH(I25,t_mins,1))) | K25: =IF(I25="","",I25/s_overall-1) | L25: =IF(K25="","",IF(K25>p_dev_tol,"strong",IF(K25<-p_dev_tol,"weak","in line"))) | M25: =IF(AND(F25<>"",H25=""),"below the conversion's range: not scored","") | N25: =IF(I25="",0,I25) -> 0 | O25: =IF(I25="",0,1) -> 0 | P25: =IF(I25="","",B25&"|"&I25)
